# Vulnerability Setup Fix Instructions

## Problem Summary

You're getting errors because:

1. Duplicate `Vulnerability` class definitions in `db/base.py`
2. Mismatched route structure between vulnerability and other routes
3. Model fields mismatch between service and database
4. Deprecated `orm_mode` configuration in Pydantic models

## Complete Fix Process

### Option 1: Quick Fix (Recommended)

Run the comprehensive fix script:

```bash
python fix_vulnerability_complete.py
```

This will automatically:
- Remove duplicate model definitions
- Check Alembic setup
- Create/update tables
- Verify everything works

### Option 2: Manual Fix Steps

1. **Fix the model duplication**:
   - Edit `db/base.py`
   - Remove the second `Vulnerability` class definition at the end of the file

2. **Update Pydantic models**:
   - Change all `orm_mode = True` to `from_attributes = True` in model files

3. **Fix the route structure**:
   - The vulnerability route file has been updated to match the service pattern
   - It now uses `get_db` from `api.deps.db` instead of `api.deps.database`

4. **Fix model field mismatches**:
   - The service and model have been updated to use consistent field names
   - Database fields now match the model fields

5. **Create/migrate tables**:
   ```bash
   # If Alembic is configured:
   alembic upgrade head
   
   # Or use the initialization script:
   python quicktara_web.py --initialize-db
   ```

6. **Test the fix**:
   ```bash
   python quicktara_web.py --debug
   ```

## Files Fixed

1. `/db/base.py` - Removed duplicate Vulnerability class
2. `/api/routes/vulnerability.py` - Updated to use correct import and service pattern
3. `/api/models/vulnerability.py` - Added missing models
4. `/api/services/vulnerability_service.py` - Fixed field name mismatches
5. Various model files - Updated from `orm_mode` to `from_attributes`

## Verification

After fixing, the application should start without errors. You can verify the vulnerability API is working by visiting:

```
http://localhost:8080/docs
```

Look for `/api/vulnerability` endpoints in the API documentation.

## Troubleshooting

If you still have issues:

1. Check the console output for specific errors
2. Ensure all dependencies are installed: `pip install -r requirements.txt`
3. Delete the database and let it recreate: `rm quicktara.db`
4. Check file permissions

## Additional Help

If problems persist, check:
- Python version (should be 3.11)
- SQLAlchemy version compatibility
- FastAPI version compatibility
